<?xml version="1.0"?>
<robot name="soccer_bot" xmlns:xacro="http://www.ros.org/wiki/xacro">

  <!-- Properties -->
  <xacro:property name="wheel_radius" value="0.03"/>
  <xacro:property name="wheel_width" value="0.02"/>
  <xacro:property name="wheel_mass" value="0.2"/>

  <link name="base_footprint"/>

    <joint name="base_footprint_joint" type="fixed">
        <parent link="base_footprint"/>
        <child link="base_link"/>
        <origin xyz="0 0 0.05"/>
    </joint>


  <!-- ================= BASE LINK ================= -->
  <link name="base_link">
    <visual>
      <origin xyz="0 0 0.05"/>
      <geometry>
        <cylinder radius="0.2" length="0.1"/>
      </geometry>
      <material name="red">
        <color rgba="1 0 0 1"/>
      </material>
    </visual>

    <collision>
      <origin xyz="0 0 0.05"/>
      <geometry>
        <cylinder radius="0.2" length="0.1"/>
      </geometry>
    </collision>

    <inertial>
      <origin xyz="0 0 0.05"/>
      <mass value="1.0"/>
      <inertia
        ixx="0.006" ixy="0.0" ixz="0.0"
        iyy="0.006" iyz="0.0"
        izz="0.012"/>
    </inertial>
  </link>

  <!-- IMU LINK -->
  <link name="imu_link">
    <visual>
      <geometry>
        <box size="0.01 0.01 0.01"/>
      </geometry>
      <material name="red"/>
    </visual>
    
    <collision>
      <geometry>
        <box size="0.01 0.01 0.01"/>
      </geometry>
    </collision>

    <inertial>
      <mass value="0.01"/>
      <inertia
        ixx="1e-5" ixy="0" ixz="0"
        iyy="1e-5" iyz="0"
        izz="1e-5"/>
    </inertial>
  </link>

  <joint name="imu_joint" type="fixed">
    <parent link="base_link"/>
    <child link="imu_link"/>
    <origin xyz="0 0 0.137"/>
  </joint>

  <!-- IR SENSOR LINK -->
  <link name="ir_link">
    <inertial>
      <mass value="0.005"/>
      <inertia ixx="1e-6" iyy="1e-6" izz="1e-6"/>
    </inertial>
  </link>

  <joint name="ir_joint" type="fixed">
    <parent link="base_link"/>
    <child link="ir_link"/>
    <origin xyz="0.22 0 0.03"/>
  </joint>

  <!-- ================= WHEEL MACRO ================= -->
  <xacro:macro name="wheel" params="name x y">
    <link name="${name}">
      <visual>
        <origin rpy="1.5708 0 0"/>
        <geometry>
          <cylinder radius="${wheel_radius}" length="${wheel_width}"/>
        </geometry>
        <material name="blue">
          <color rgba="0 0 1 1"/>
        </material>
      </visual>

      <collision>
        <origin rpy="1.5708 0 0"/>
        <geometry>
          <cylinder radius="${wheel_radius}" length="${wheel_width}"/>
        </geometry>
      </collision>

      <inertial>
        <mass value="${wheel_mass}"/>
        <inertia
          ixx="0.0001" ixy="0" ixz="0"
          iyy="0.0001" iyz="0"
          izz="0.0001"/>
      </inertial>
    </link>

    <joint name="${name}_joint" type="continuous">
      <parent link="base_link"/>
      <child link="${name}"/>
      <origin xyz="${x} ${y} 0.0"/>
      <axis xyz="0 1 0"/>
      <dynamics damping="0.1" friction="0.0"/>
    </joint>
  </xacro:macro>

  <!-- ================= WHEELS ================= -->
  <xacro:wheel name="front_left_wheel"  x="0.15"  y="0.15"/>
  <xacro:wheel name="front_right_wheel" x="0.15"  y="-0.15"/>
  <xacro:wheel name="back_left_wheel"   x="-0.15" y="0.15"/>
  <xacro:wheel name="back_right_wheel"  x="-0.15" y="-0.15"/>

    <!-- Camera -->
    <link name="camera_link">
      <visual>
        <geometry>
          <box size="0.02 0.02 0.02"/>
        </geometry>
        <material name="blue"/>
      </visual>
    </link>

    <joint name="camera_joint" type="fixed">
      <parent link="base_link"/>
      <child link="camera_link"/>
      <origin xyz="0.18 0 0.11" rpy="0 0 0"/>
    </joint>

    <!-- Kicker (solenoid valve) -->
    <link name="kicker_link">
        <visual>
            <geometry>
            <box size="0.05 0.02 0.01"/>
            </geometry>
            <material name="black"/>
        </visual>
    
      <inertial>
        <origin xyz="0 0 0"/>
        <mass value="0.1"/>
        <inertia
          ixx="0.0001" ixy="0.0" ixz="0.0"
          iyy="0.0001" iyz="0.0"
          izz="0.0001"/>
      </inertial>
    </link>

    <joint name="kicker_joint" type="prismatic">
        <parent link="base_link"/>
        <child link="kicker_link"/>
        <origin xyz="0.22 0 0.03"/>
        <axis xyz="1 0 0"/>
        <limit lower="0.0" upper="0.03" effort="50" velocity="2"/>
    </joint>

      <!-- ================= GRIPPER MACRO ================= -->
    <xacro:macro name="gripper" params="name x y yaw">
      <link name="${name}">
        <visual>
          <origin rpy="1.5708 0 0"/>
          <geometry>
            <cylinder radius="0.015" length="0.03"/>
          </geometry>
          <material name="black">
            <color rgba="0 0 0 1"/>
          </material>
        </visual>

        <collision>
          <origin rpy="1.5708 0 0"/>
          <geometry>
            <cylinder radius="0.015" length="0.03"/>
          </geometry>
        </collision>

        <inertial>
          <mass value="0.05"/>
          <inertia
            ixx="0.00002" ixy="0" ixz="0"
            iyy="0.00002" iyz="0"
            izz="0.00002"/>
        </inertial>
      </link>

      <joint name="${name}_joint" type="continuous">
        <parent link="base_link"/>
        <child link="${name}"/>
        <origin xyz="${x} ${y} 0.04" rpy="0 0 ${yaw}"/>
        <axis xyz="0 1 0"/>
      </joint>
    </xacro:macro>

  <!-- ================= GRIPPERS ================= -->
    <xacro:gripper name="left_gripper_wheel"  x="0.2"  y="0.05" yaw="-0.3"/>
    <xacro:gripper name="right_gripper_wheel" x="0.2"  y="-0.05" yaw="0.3"/>

  <!-- ================= LIDAR ================= -->
  <link name="lidar_link">
    <visual>
      <geometry>
        <cylinder radius="0.03" length="0.03"/>
      </geometry>
      <material name="black"/>
    </visual>

    <collision>
      <geometry>
        <cylinder radius="0.03" length="0.03"/>
      </geometry>
    </collision>

    <inertial>
      <mass value="0.1"/>
      <inertia
        ixx="0.0001" ixy="0" ixz="0"
        iyy="0.0001" iyz="0"
        izz="0.0001"/>
    </inertial>
  </link>

  <joint name="lidar_joint" type="fixed">
    <parent link="base_link"/>
    <child link="lidar_link"/>
    <origin xyz="0 0 0.116" rpy="0 0 0"/>
  </joint>


    <!-- Gazebo Condition -->
  <gazebo reference="base_link">
    <selfCollide>false</selfCollide>
    </gazebo>
  <gazebo reference="front_left_wheel">
    <selfCollide>false</selfCollide>
    </gazebo>
  <gazebo reference="front_right_wheel">
    <selfCollide>false</selfCollide>
    </gazebo>
  <gazebo reference="back_left_wheel">
    <selfCollide>false</selfCollide>
    </gazebo>
  <gazebo reference="back_right_wheel">
    <selfCollide>false</selfCollide>
    </gazebo>
  <gazebo reference="camera_link">
    <selfCollide>false</selfCollide>
    </gazebo>
  <gazebo reference="kicker_link">
    <selfCollide>false</selfCollide>
    </gazebo>
  <gazebo reference="left_gripper_wheel">
    <selfCollide>false</selfCollide>
    </gazebo>
  <gazebo reference="right_gripper_wheel">
    <selfCollide>false</selfCollide>
    </gazebo>
  <gazebo reference="lidar_link">
    <selfCollide>false</selfCollide>
    </gazebo>
  <gazebo reference="imu_link">
    <selfCollide>false</selfCollide>
    </gazebo>

    <!-- LIDAR Sensor -->
    <gazebo reference="lidar_link">
      <sensor name="lidar" type="gpu_lidar">
        <always_on>true</always_on>
        <update_rate>10</update_rate>
        <visualize>true</visualize>

        <topic>scan</topic>

        <lidar>
          <scan>
            <horizontal>
              <samples>360</samples>
              <resolution>1</resolution>
              <min_angle>-3.14159</min_angle>
              <max_angle>3.14159</max_angle>
            </horizontal>
          </scan>

          <range>
            <min>0.05</min>
            <max>10.0</max>
            <resolution>0.01</resolution>
          </range>
        </lidar>

      </sensor>
    </gazebo>


  <!-- Wheel Friction Macro -->
  <xacro:macro name="wheel_friction" params="wheel">
  <gazebo reference="${wheel}">
    <surface>
      <friction>
        <ode>
          <mu>1.2</mu>
          <mu2>1.2</mu2>
        </ode>
      </friction>
    </surface>
  </gazebo>
</xacro:macro>

<!-- Apply friction to all wheels -->
<xacro:wheel_friction wheel="front_left_wheel"/>
<xacro:wheel_friction wheel="front_right_wheel"/>
<xacro:wheel_friction wheel="back_left_wheel"/>
<xacro:wheel_friction wheel="back_right_wheel"/>


  <!-- Gripper Friction Gazebo -->
  <gazebo reference="left_gripper_wheel">
    <mu1>1.2</mu1>
    <mu2>1.2</mu2>
  </gazebo>
  <gazebo reference="right_gripper_wheel">
    <mu1>1.2</mu1>
    <mu2>1.2</mu2>
  </gazebo>

  <!-- Diff Drive Plugin -->
  <gazebo>
    <plugin
      filename="gz-sim-diff-drive-system"
      name="gz::sim::systems::DiffDrive">

      <left_joint>front_left_wheel_joint</left_joint>
      <left_joint>back_left_wheel_joint</left_joint>

      <right_joint>front_right_wheel_joint</right_joint>
      <right_joint>back_right_wheel_joint</right_joint>

      <wheel_separation>0.30</wheel_separation>
      <wheel_radius>0.03</wheel_radius>

      <odom_publish_frequency>50</odom_publish_frequency>
      <topic>cmd_vel</topic>
      <odom_topic>odom</odom_topic>
      <frame_id>odom</frame_id>
      <child_frame_id>base_link</child_frame_id>
  </plugin>
</gazebo>

<!-- Sensors Plugin -->
<gazebo>
    <plugin
      filename="gz-sim-sensors-system"
      name="gz::sim::systems::Sensors"/>
    <plugin
      filename="gz-sim-imu-system"
      name="gz::sim::systems::Imu"/>
</gazebo>

<!-- Gazebo Sensor for Camera -->
<gazebo reference="camera_link">
    <sensor name="camera" type="camera">
      <always_on>true</always_on>
      <visualize>true</visualize>
      <update_rate>30</update_rate>

      <camera>
        <horizontal_fov>1.047</horizontal_fov>
        <image>
          <width>640</width>
          <height>480</height>
          <format>R8G8B8</format>
        </image>
        <clip>
          <near>0.1</near>
          <far>100</far>
        </clip>
      </camera>

      <topic>/camera/image</topic>
    </sensor>
  </gazebo>

  <!-- Gazebo Sensor for IMU -->
  <gazebo reference="base_link">
    <sensor name="imu_sensor" type="imu">
      <always_on>true</always_on>
      <update_rate>200</update_rate>
      <visualize>false</visualize>
      <topic>/imu/data</topic>
      <imu>
        <angular_velocity>
          <x><noise type="gaussian"><mean>0</mean><stddev>0.00001</stddev></noise></x>
          <y><noise type="gaussian"><mean>0</mean><stddev>0.00001</stddev></noise></y>
          <z><noise type="gaussian"><mean>0</mean><stddev>0.00001</stddev></noise></z>
        </angular_velocity>
        <linear_acceleration>
          <x><noise type="gaussian"><mean>0</mean><stddev>0.001</stddev></noise></x>
          <y><noise type="gaussian"><mean>0</mean><stddev>0.001</stddev></noise></y>
          <z><noise type="gaussian"><mean>0</mean><stddev>0.001</stddev></noise></z>
        </linear_acceleration>
      </imu>
    </sensor>
  </gazebo>

  <!-- Gazebo Sensor for IR -->
  <gazebo reference="ir_link">
    <sensor name="ir_sensor" type="gpu_lidar">
      <always_on>true</always_on>
      <update_rate>50</update_rate>
      <topic>/ir/beam</topic>

      <lidar>
        <scan>
          <horizontal>
            <samples>1</samples>
            <min_angle>0</min_angle>
            <max_angle>0</max_angle>
          </horizontal>
        </scan>
        <range>
          <min>0.01</min>
          <max>0.15</max>
        </range>
      </lidar>
    </sensor>
  </gazebo>

</robot>